<?xml version="1.0" ?>
<robot name="robot_description" xmlns:xacro="http://www.ros.org/wiki/xacro">

<xacro:include filename="$(find robot_description)/urdf/materials.xacro" />
<xacro:include filename="$(find robot_description)/urdf/robot_description.ros2control" />
<xacro:include filename="$(find robot_description)/urdf/robot_description.gazebo" />
<link name="base_link">
  <inertial>
    <origin xyz="-0.005885456345497542 -2.142360908145288e-17 0.05578139130205967" rpy="0 0 0"/>
    <mass value="3.600007375840053"/>
    <inertia ixx="0.012571" iyy="0.026733" izz="0.035965" ixy="0.0" iyz="-0.0" ixz="0.000918"/>
  </inertial>
  <visual>
    <origin xyz="0 0 0" rpy="0 0 0"/>
    <geometry>
      <mesh filename="file://$(find robot_description)/meshes/base_link.stl" scale="0.001 0.001 0.001"/>
    </geometry>
    <material name="silver"/>
  </visual>
  <collision>
    <origin xyz="0 0 0" rpy="0 0 0"/>
    <geometry>
      <mesh filename="file://$(find robot_description)/meshes/base_link.stl" scale="0.001 0.001 0.001"/>
    </geometry>
  </collision>
</link>

<link name="left_wheel_1">
  <inertial>
    <origin xyz="-1.8082757513582237e-14 0.012499999999999983 6.938893903907228e-18" rpy="0 0 0"/>
    <mass value="0.27350263855685797"/>
    <inertia ixx="0.000189" iyy="0.00035" izz="0.000189" ixy="-0.0" iyz="-0.0" ixz="-0.0"/>
  </inertial>
  <visual>
    <origin xyz="0.1 -0.11 -0.05" rpy="0 0 0"/>
    <geometry>
      <mesh filename="file://$(find robot_description)/meshes/left_wheel_1.stl" scale="0.001 0.001 0.001"/>
    </geometry>
    <material name="silver"/>
  </visual>
  <collision>
    <origin xyz="0.1 -0.11 -0.05" rpy="0 0 0"/>
    <geometry>
      <mesh filename="file://$(find robot_description)/meshes/left_wheel_1.stl" scale="0.001 0.001 0.001"/>
    </geometry>
  </collision>
</link>

<link name="right_wheel_1">
  <inertial>
    <origin xyz="-1.8082757513582237e-14 -0.012499999999999997 6.938893903907228e-18" rpy="0 0 0"/>
    <mass value="0.27350263855685797"/>
    <inertia ixx="0.000189" iyy="0.00035" izz="0.000189" ixy="0.0" iyz="0.0" ixz="-0.0"/>
  </inertial>
  <visual>
    <origin xyz="0.1 0.11 -0.05" rpy="0 0 0"/>
    <geometry>
      <mesh filename="file://$(find robot_description)/meshes/right_wheel_1.stl" scale="0.001 0.001 0.001"/>
    </geometry>
    <material name="silver"/>
  </visual>
  <collision>
    <origin xyz="0.1 0.11 -0.05" rpy="0 0 0"/>
    <geometry>
      <mesh filename="file://$(find robot_description)/meshes/right_wheel_1.stl" scale="0.001 0.001 0.001"/>
    </geometry>
  </collision>
</link>

<link name="caster_1">
  <inertial>
    <origin xyz="-0.04999999999999999 0.0 -0.009374999999999998" rpy="0 0 0"/>
    <mass value="0.25689064927791533"/>
    <inertia ixx="4.2e-05" iyy="4.2e-05" izz="6.4e-05" ixy="0.0" iyz="0.0" ixz="0.0"/>
  </inertial>
  <visual>
    <origin xyz="-0.15 0.0 -0.025" rpy="0 0 0"/>
    <geometry>
      <mesh filename="file://$(find robot_description)/meshes/caster_1.stl" scale="0.001 0.001 0.001"/>
    </geometry>
    <material name="silver"/>
  </visual>
  <collision>
    <origin xyz="-0.15 0.0 -0.025" rpy="0 0 0"/>
    <geometry>
      <mesh filename="file://$(find robot_description)/meshes/caster_1.stl" scale="0.001 0.001 0.001"/>
    </geometry>
  </collision>
</link>

<link name="lidar_1">
  <inertial>
    <origin xyz="0.0 5.904170394414034e-18 0.01271329027872195" rpy="0 0 0"/>
    <mass value="1.5115445803512537"/>
    <inertia ixx="0.001005" iyy="0.001005" izz="0.001857" ixy="0.0" iyz="0.0" ixz="0.0"/>
  </inertial>
  <visual>
    <origin xyz="0.05 -0.0 -0.125" rpy="0 0 0"/>
    <geometry>
      <mesh filename="file://$(find robot_description)/meshes/lidar_1.stl" scale="0.001 0.001 0.001"/>
    </geometry>
    <material name="silver"/>
  </visual>
  <collision>
    <origin xyz="0.05 -0.0 -0.125" rpy="0 0 0"/>
    <geometry>
      <mesh filename="file://$(find robot_description)/meshes/lidar_1.stl" scale="0.001 0.001 0.001"/>
    </geometry>
  </collision>
</link>

<joint name="Revolute 1" type="continuous">
  <origin xyz="-0.1 0.11 0.05" rpy="0 0 0"/>
  <parent link="base_link"/>
  <child link="left_wheel_1"/>
  <axis xyz="0.0 1.0 0.0"/>
</joint>

<joint name="Revolute 2" type="continuous">
  <origin xyz="-0.1 -0.11 0.05" rpy="0 0 0"/>
  <parent link="base_link"/>
  <child link="right_wheel_1"/>
  <axis xyz="0.0 -1.0 0.0"/>
</joint>

<joint name="Rigid 3" type="fixed">
  <origin xyz="0.15 0.0 0.025" rpy="0 0 0"/>
  <parent link="base_link"/>
  <child link="caster_1"/>
</joint>

<joint name="Rigid 4" type="fixed">
  <origin xyz="-0.05 0.0 0.125" rpy="0 0 0"/>
  <parent link="base_link"/>
  <child link="lidar_1"/>
</joint>

</robot>
